# 47장 에러 처리

### 47.1장 에러 처리의 필요성

- 에러가 발생하지 않는 코드를 작성하는 것은 불가능하기 때문에 발생한 에러에 대해 대처하는 방법이 중요하다.

- try....catch문을 사용해 발생한 에러에 적절하게 대응하면 프로그램이 강제 종료되지 않고 계속해서 코드를 실행시킬 수 있다.

- 아래의 코드를 살펴보자.

  - querySelector 메서드는 인수로 전달한 CSS 선택자 문자열로 DOM에서 요소 노드를 찾을 수 없는 경우 에러를 발생시키지 않고 null을 반환한다. 따로 에러 처리를 해주지 않으면 아래 코드에서 에러로 이어질 가능성이 크고 프로그램은 강제 종료될 것이다.

  ```javascript
  // DOM에 button 요소가 존재하는 경우 querySelector 메서드는 에러를 발생시키지 않고 null을 반환한다.
  const $button = document.querySelector('button'); // null
  $button?.classList.add('disabled');
  ```

  - 기본적으로 에러가 발생하지 않는 코드를 짜면 괜찮겠지만, 현실적으로 불가능하다. 따라서 작성한 코드에서는 언제나 에러나 예외적인 상황이 발생할 수 있다는 것을 전제하고 이에 대응하는 코드를 작성하는 것이 중요하다.



<br>

### 47.2장 try...catch...finally 문

---

- 기본적으로, 에러 처리를 구현하는 방법은 크게 두 가지가 존재한다.
  1. querySelector나 Array#find 메서드처럼 예외적인 상황이 발생하면 반환하는 값을 if문이나 단축 평가 또는 옵셔널 체이닝 연산자를 통해 확인해서 처리하는 방법
  2. 에러 처리 코드를 미리 등록해두고 에러가 발생하면 에러 처리 코드로 점프하도록 하는 방법
     - try...catch...finally문이 여기에 해당한다. -> 일반적으로, 이 방법을 에러 처리라고 한다.



- **try...catch...finally문**

  - try...catch...finally문은 3개의 코드 블록으로 구성된다.

  ```javascript
  try {
    // 실행할 코드(에러가 발생할 가능성이 있는 코드)
  } catch (err) {
    // try 코드 블록에서 에러가 발생하면 이 코드 블록의 코드가 실행된다.
    // err에는 try 코드 블록에서 발생한 Error 객체가 전달된다.
  } finnaly {
    // 에러 발생과 상관없이 반드시 한 번 실행된다.
  }
  ```

  - 먼저, try 코드 블록이 실행된다. 이때 try 코드 블록에 포함된 문 중에서 에러가 발생하면 발생한 에러는 catch문의 err 변수에 전달되고 catch 코드 블록이 실행된다.

  - catch문의 err 변수(어떠한 이름도 상관없다)는 try 코드 블록에 포함된 문 중에서 에러가 발생하면 생성되고 catch 코드 블록에서만 유효하다.

  - Finally 코드 블록은 에러 발생과 상관없이 반드시 한 번 실행된다.

    

<br>

### 47.3 Error 객체

---

- Error 생성자 함수는 에러 객체를 생성한다. 

- Error 생성자 함수에는 에러를 상세히 설명하는 에러 메세지를 인수로 전달할 수 있다.

  ```javascript
  const error = new Error('invalid');
  ```

- Error 생성자 함수가 생성한 에러 객체는 message 프로퍼티와 stack 프로퍼티를 갖는다. 
  - Message 프로퍼티의 값은 Error 생성자 함수에 인수로 전달한 에러 메세지이다.
  - stack 프로퍼티의 값은 에러를 발생시킨 콜스택의 호출 정보를 나타내는 문자열이며 디버깅 목적으로 사용한다.

<br>

### 47.4 throw 문

---

- Error 생성자 함수로 에러 객체를 생성한다고 에러가 발생하는 것은 아니다. 즉 에러 객체 생성과 에러 발생은 의미가 다르다.

- 에러를 발생시키려면 try 코드 블록에서 throw문으로 에러 객체를 던져야 한다.

  ```javascript
  try {
    // 에러 객체를 던지면 catch 코드 블록이 실행되기 시작한다.
    throw new Error('something wrong');
  } catch (error) {
    console.log(error);
  }
  ```

<br>

### 47.5 에러의 전파

---

- 에러는 호출자 방향으로 전파된다.

  - 즉, 콜 스택의 아래 방향(실행 중인 실행 컨텍스트가 푸시되기 직전에 푸시된 실행 컨텍스트 방향)으로 전파된다.

    ```javascript
    const foo = () => {
      throw Error('foo에서 발생한 에러'); // ④
    };
    
    const bar = () => {
      foo(); // ③
    };
    
    const baz = () => {
      bar(); // ②
    };
    
    try {
      baz(); // ①
    } catch (err) {
      console.error(err);
    }
    ```

    - 1에서 baz 함수를 호출하면 2에서 bar함수가 호출되고 3에서 foo함수가 호출되고 foo함수는 4에서 에러를 throw한다. 이때 foo함수가 throw한 에러는 다음과 같이 호출자에게 전파되어 전역에서 캐치된다.

- throw된 에러를 캐치하지 않으면 호출자 방향으로 전파된다. 이때 throw된 에러를 캐치하여 적절히 대응하면 프로그램을 강제 종료 시키지 않고 코드의 실행 흐름을 복구할 수 있다. 

- throw된 에러를 어디에서도 캐치하지 않으면 프로그램은 강제 종료된다.